Workbook

Sheet Pipeline
A1: Lead ID | B1: Company Name | C1: Industry | D1: Company Size | E1: Contact Name | F1: Contact Title | G1: Email | H1: Lead Source | I1: Date Created | J1: Sales Rep | K1: Budget Score | L1: Authority Score | M1: Need Score | N1: Timeline Score | O1: BANT Total | P1: Qualified? (15+) | Q1: Stage | R1: Deal Value (INR) | S1: Win Probability % | T1: Weighted Value (INR) | U1: Expected Close Date | V1: Actual Close Date | W1: Days in Pipeline | X1: Lost Reason
A2: LD2001 | B2: Vertex Traders | C2: Retail | D2: Small (1-50) | E2: Tanya | F2: VP Sales | G2: tanya@vertex.com | H2: Partner Channel | I2: 28-11-2025 | J2: Divya Nair | K2: 5 | L2: 3 | M2: 4 | N2: 4 | O2: =SUM(K2:N2) -> 16 | P2: =IF(O2>=15,"Yes","No") -> Yes | Q2: Closed Won | R2: 194000 | S2: 1 | T2: =R2*S2 -> 194000 | U2: 14-01-2026 | V2: 07-01-2026 | W2: 40
A3: LD2002 | B3: Bluepeak Retail | C3: FMCG | D3: Small (1-50) | E3: Kabir | F3: Procurement Manager | G3: kabir@bluepeak.com | H3: Referral | I3: 11-02-2026 | J3: Rohit Malhotra | K3: 4 | L3: 4 | M3: 5 | N3: 4 | O3: =SUM(K3:N3) -> 17 | P3: =IF(O3>=15,"Yes","No") -> Yes | Q3: Closed Lost | R3: 229000 | S3: 0 | T3: =R3*S3 -> 0 | U3: 17-04-2026 | V3: 23-03-2026 | W3: 40 | X3: Budget too high
A4: LD2003 | B4: Bluepeak Solutions | C4: Healthcare | D4: Mid-Market (51-500) | E4: Pooja | F4: COO | G4: pooja@bluepeak.com | H4: LinkedIn Outreach | I4: 14-03-2026 | J4: Sneha Iyer | K4: 1 | L4: 2 | M4: 3 | N4: 2 | O4: =SUM(K4:N4) -> 8 | P4: =IF(O4>=15,"Yes","No") -> No | Q4: Contacted | R4: 578000 | S4: 0.15 | T4: =R4*S4 -> 86700 | U4: 18-04-2026
A5: LD2004 | B5: Crestline Enterprises | C5: Retail | D5: Enterprise (500+) | E5: Kavya | F5: Procurement Manager | G5: kavya@crestline.com | H5: Inbound - Website | I5: 05-04-2026 | J5: Karan Bhatia | K5: 4 | L5: 3 | M5: 3 | N5: 3 | O5: =SUM(K5:N5) -> 13 | P5: =IF(O5>=15,"Yes","No") -> No | Q5: Proposal Sent | R5: 3009000 | S5: 0.55 | T5: =R5*S5 -> 1654950 | U5: 16-06-2026
A6: LD2005 | B6: Nova Mart | C6: E-commerce | D6: Small (1-50) | E6: Kavya | F6: Founder/CEO | G6: kavya@nova.com | H6: Referral | I6: 13-04-2026 | J6: Ananya Kapoor | K6: 4 | L6: 2 | M6: 5 | N6: 4 | O6: =SUM(K6:N6) -> 15 | P6: =IF(O6>=15,"Yes","No") -> Yes | Q6: Closed Lost | R6: 213000 | S6: 0 | T6: =R6*S6 -> 0 | U6: 25-05-2026 | V6: 02-05-2026 | W6: 19 | X6: Not enough authority to buy
A7: LD2006 | B7: Summit Solutions | C7: E-commerce | D7: Small (1-50) | E7: Zara | F7: COO | G7: zara@summit.com | H7: Cold Outbound | I7: 30-04-2025 | J7: Rohit Malhotra | K7: 1 | L7: 1 | M7: 1 | N7: 1 | O7: =SUM(K7:N7) -> 4 | P7: =IF(O7>=15,"Yes","No") -> No | Q7: Closed Lost | R7: 191000 | S7: 0 | T7: =R7*S7 -> 0 | U7: 14-07-2025 | V7: 14-05-2025 | W7: 14 | X7: Not enough authority to buy
A8: LD2007 | B8: Ember Ventures | C8: Retail | D8: Small (1-50) | E8: Ishita | F8: Procurement Manager | G8: ishita@ember.com | H8: Partner Channel | I8: 25-01-2026 | J8: Rohit Malhotra | K8: 5 | L8: 3 | M8: 3 | N8: 5 | O8: =SUM(K8:N8) -> 16 | P8: =IF(O8>=15,"Yes","No") -> Yes | Q8: Closed Won | R8: 202000 | S8: 1 | T8: =R8*S8 -> 202000 | U8: 22-02-2026 | V8: 03-03-2026 | W8: 37
A9: LD2008 | B9: Northstar Traders | C9: FMCG | D9: Small (1-50) | E9: Dev | F9: VP Sales | G9: dev@northstar.com | H9: Cold Outbound | I9: 06-02-2026 | J9: Karan Bhatia | K9: 1 | L9: 1 | M9: 3 | N9: 1 | O9: =SUM(K9:N9) -> 6 | P9: =IF(O9>=15,"Yes","No") -> No | Q9: Contacted | R9: 178000 | S9: 0.15 | T9: =R9*S9 -> 26700 | U9: 26-03-2026
A10: LD2009 | B10: Ironclad Industries | C10: Retail | D10: Small (1-50) | E10: Arjun | F10: COO | G10: arjun@ironclad.com | H10: Referral | I10: 15-04-2025 | J10: Sneha Iyer | K10: 5 | L10: 4 | M10: 5 | N10: 4 | O10: =SUM(K10:N10) -> 18 | P10: =IF(O10>=15,"Yes","No") -> Yes | Q10: Contacted | R10: 156000 | S10: 0.15 | T10: =R10*S10 -> 23400 | U10: 13-06-2025
A11: LD2010 | B11: Ember Industries | C11: FMCG | D11: Small (1-50) | E11: Aarav | F11: Marketing Director | G11: aarav@ember.com | H11: Cold Outbound | I11: 08-01-2026 | J11: Karan Bhatia | K11: 1 | L11: 3 | M11: 4 | N11: 1 | O11: =SUM(K11:N11) -> 9 | P11: =IF(O11>=15,"Yes","No") -> No | Q11: Qualified | R11: 196000 | S11: 0.35 | T11: =R11*S11 -> 68600 | U11: 27-02-2026
A12: LD2011 | B12: Redshift Enterprises | C12: Retail | D12: Mid-Market (51-500) | E12: Riya | F12: COO | G12: riya@redshift.com | H12: Inbound - Website | I12: 06-01-2026 | J12: Divya Nair | K12: 3 | L12: 2 | M12: 5 | N12: 3 | O12: =SUM(K12:N12) -> 13 | P12: =IF(O12>=15,"Yes","No") -> No | Q12: Contacted | R12: 891000 | S12: 0.15 | T12: =R12*S12 -> 133650 | U12: 11-02-2026
A13: LD2012 | B13: Ironclad Group | C13: E-commerce | D13: Mid-Market (51-500) | E13: Kabir | F13: Procurement Manager | G13: kabir@ironclad.com | H13: Cold Outbound | I13: 17-08-2025 | J13: Rohit Malhotra | K13: 1 | L13: 2 | M13: 2 | N13: 1 | O13: =SUM(K13:N13) -> 6 | P13: =IF(O13>=15,"Yes","No") -> No | Q13: Contacted | R13: 587000 | S13: 0.15 | T13: =R13*S13 -> 88050 | U13: 28-10-2025
A14: LD2013 | B14: Foxglove Enterprises | C14: Education | D14: Enterprise (500+) | E14: Kavya | F14: Head of Operations | G14: kavya@foxglove.com | H14: LinkedIn Outreach | I14: 31-12-2025 | J14: Karan Bhatia | K14: 2 | L14: 3 | M14: 2 | N14: 1 | O14: =SUM(K14:N14) -> 8 | P14: =IF(O14>=15,"Yes","No") -> No | Q14: Contacted | R14: 2711000 | S14: 0.15 | T14: =R14*S14 -> 406650 | U14: 17-02-2026
A15: LD2014 | B15: Cobalt Enterprises | C15: E-commerce | D15: Mid-Market (51-500) | E15: Vivaan | F15: Head of Operations | G15: vivaan@cobalt.com | H15: Referral | I15: 14-08-2025 | J15: Karan Bhatia | K15: 3 | L15: 4 | M15: 3 | N15: 3 | O15: =SUM(K15:N15) -> 13 | P15: =IF(O15>=15,"Yes","No") -> No | Q15: Contacted | R15: 614000 | S15: 0.15 | T15: =R15*S15 -> 92100 | U15: 03-10-2025
A16: LD2015 | B16: Nova Industries | C16: FMCG | D16: Mid-Market (51-500) | E16: Yash | F16: Founder/CEO | G16: yash@nova.com | H16: LinkedIn Outreach | I16: 02-02-2026 | J16: Rohit Malhotra | K16: 2 | L16: 1 | M16: 4 | N16: 2 | O16: =SUM(K16:N16) -> 9 | P16: =IF(O16>=15,"Yes","No") -> No | Q16: Closed Lost | R16: 824000 | S16: 0 | T16: =R16*S16 -> 0 | U16: 02-03-2026 | V16: 03-03-2026 | W16: 29 | X16: Budget too high
A17: LD2016 | B17: Lumen Group | C17: FMCG | D17: Small (1-50) | E17: Kabir | F17: VP Sales | G17: kabir@lumen.com | H17: LinkedIn Outreach | I17: 01-05-2026 | J17: Rohit Malhotra | K17: 1 | L17: 4 | M17: 2 | N17: 2 | O17: =SUM(K17:N17) -> 9 | P17: =IF(O17>=15,"Yes","No") -> No | Q17: Contacted | R17: 214000 | S17: 0.15 | T17: =R17*S17 -> 32100 | U17: 29-05-2026
A18: LD2017 | B18: Foxglove Enterprises | C18: Logistics | D18: Mid-Market (51-500) | E18: Yash | F18: Growth Lead | G18: yash@foxglove.com | H18: Inbound - Website | I18: 15-09-2025 | J18: Sneha Iyer | K18: 3 | L18: 1 | M18: 4 | N18: 4 | O18: =SUM(K18:N18) -> 12 | P18: =IF(O18>=15,"Yes","No") -> No | Q18: Contacted | R18: 550000 | S18: 0.15 | T18: =R18*S18 -> 82500 | U18: 08-10-2025
A19: LD2018 | B19: Nova Industries | C19: FMCG | D19: Small (1-50) | E19: Riya | F19: Founder/CEO | G19: riya@nova.com | H19: Referral | I19: 29-05-2026 | J19: Karan Bhatia | K19: 3 | L19: 4 | M19: 5 | N19: 3 | O19: =SUM(K19:N19) -> 15 | P19: =IF(O19>=15,"Yes","No") -> Yes | Q19: New Lead | R19: 185000 | S19: 0.05 | T19: =R19*S19 -> 9250 | U19: 26-07-2026
A20: LD2019 | B20: Summit Retail | C20: Retail | D20: Small (1-50) | E20: Tanya | F20: Marketing Director | G20: tanya@summit.com | H20: Cold Outbound | I20: 30-04-2026 | J20: Divya Nair | K20: 3 | L20: 2 | M20: 2 | N20: 2 | O20: =SUM(K20:N20) -> 9 | P20: =IF(O20>=15,"Yes","No") -> No | Q20: Contacted | R20: 136000 | S20: 0.15 | T20: =R20*S20 -> 20400 | U20: 26-05-2026
A21: LD2020 | B21: Ember Solutions | C21: FMCG | D21: Small (1-50) | E21: Yash | F21: Procurement Manager | G21: yash@ember.com | H21: Referral | I21: 11-10-2025 | J21: Ananya Kapoor | K21: 3 | L21: 1 | M21: 4 | N21: 3 | O21: =SUM(K21:N21) -> 11 | P21: =IF(O21>=15,"Yes","No") -> No | Q21: Qualified | R21: 206000 | S21: 0.35 | T21: =R21*S21 -> 72100 | U21: 12-11-2025
A22: LD2021 | B22: Palm Industries | C22: Healthcare | D22: Enterprise (500+) | E22: Zara | F22: Head of Operations | G22: zara@palm.com | H22: LinkedIn Outreach | I22: 11-09-2025 | J22: Sneha Iyer | K22: 2 | L22: 2 | M22: 1 | N22: 3 | O22: =SUM(K22:N22) -> 8 | P22: =IF(O22>=15,"Yes","No") -> No | Q22: New Lead | R22: 1970000 | S22: 0.05 | T22: =R22*S22 -> 98500 | U22: 13-10-2025
A23: LD2022 | B23: Zenith Enterprises | C23: E-commerce | D23: Small (1-50) | E23: Aditya | F23: IT Manager | G23: aditya@zenith.com | H23: Cold Outbound | I23: 06-02-2026 | J23: Ananya Kapoor | K23: 1 | L23: 2 | M23: 2 | N23: 2 | O23: =SUM(K23:N23) -> 7 | P23: =IF(O23>=15,"Yes","No") -> No | Q23: Contacted | R23: 139000 | S23: 0.15 | T23: =R23*S23 -> 20850 | U23: 16-04-2026
A24: LD2023 | B24: Driftwood Group | C24: Hospitality | D24: Small (1-50) | E24: Riya | F24: Growth Lead | G24: riya@driftwood.com | H24: Partner Channel | I24: 21-05-2025 | J24: Karan Bhatia | K24: 5 | L24: 4 | M24: 5 | N24: 3 | O24: =SUM(K24:N24) -> 17 | P24: =IF(O24>=15,"Yes","No") -> Yes | Q24: New Lead | R24: 234000 | S24: 0.05 | T24: =R24*S24 -> 11700 | U24: 20-06-2025
A25: LD2024 | B25: Meridian Traders | C25: E-commerce | D25: Small (1-50) | E25: Vivaan | F25: IT Manager | G25: vivaan@meridian.com | H25: Inbound - Website | I25: 18-02-2026 | J25: Sneha Iyer | K25: 4 | L25: 2 | M25: 3 | N25: 4 | O25: =SUM(K25:N25) -> 13 | P25: =IF(O25>=15,"Yes","No") -> No | Q25: Closed Won | R25: 154000 | S25: 1 | T25: =R25*S25 -> 154000 | U25: 17-03-2026 | V25: 23-03-2026 | W25: 33
A26: LD2025 | B26: Driftwood Solutions | C26: E-commerce | D26: Mid-Market (51-500) | E26: Nikhil | F26: Founder/CEO | G26: nikhil@driftwood.com | H26: Referral | I26: 06-10-2025 | J26: Rohit Malhotra | K26: 4 | L26: 4 | M26: 3 | N26: 5 | O26: =SUM(K26:N26) -> 16 | P26: =IF(O26>=15,"Yes","No") -> Yes | Q26: New Lead | R26: 544000 | S26: 0.05 | T26: =R26*S26 -> 27200 | U26: 19-12-2025
A27: LD2026 | B27: Willow Group | C27: Retail | D27: Small (1-50) | E27: Vivaan | F27: IT Manager | G27: vivaan@willow.com | H27: LinkedIn Outreach | I27: 22-05-2026 | J27: Rohit Malhotra | K27: 3 | L27: 1 | M27: 4 | N27: 2 | O27: =SUM(K27:N27) -> 10 | P27: =IF(O27>=15,"Yes","No") -> No | Q27: Qualified | R27: 236000 | S27: 0.35 | T27: =R27*S27 -> 82600 | U27: 16-06-2026
A28: LD2027 | B28: Orbit Industries | C28: FMCG | D28: Small (1-50) | E28: Arjun | F28: VP Sales | G28: arjun@orbit.com | H28: Cold Outbound | I28: 05-05-2025 | J28: Sneha Iyer | K28: 3 | L28: 2 | M28: 1 | N28: 1 | O28: =SUM(K28:N28) -> 7 | P28: =IF(O28>=15,"Yes","No") -> No | Q28: Contacted | R28: 242000 | S28: 0.15 | T28: =R28*S28 -> 36300 | U28: 09-06-2025
A29: LD2028 | B29: Havenly Retail | C29: E-commerce | D29: Small (1-50) | E29: Arjun | F29: VP Sales | G29: arjun@havenly.com | H29: Inbound - Website | I29: 05-07-2025 | J29: Rohit Malhotra | K29: 3 | L29: 2 | M29: 2 | N29: 3 | O29: =SUM(K29:N29) -> 10 | P29: =IF(O29>=15,"Yes","No") -> No | Q29: Contacted | R29: 196000 | S29: 0.15 | T29: =R29*S29 -> 29400 | U29: 11-08-2025
A30: LD2029 | B30: Ironclad Ventures | C30: Hospitality | D30: Mid-Market (51-500) | E30: Sana | F30: Marketing Director | G30: sana@ironclad.com | H30: Referral | I30: 16-01-2025 | J30: Divya Nair | K30: 2 | L30: 4 | M30: 3 | N30: 5 | O30: =SUM(K30:N30) -> 14 | P30: =IF(O30>=15,"Yes","No") -> No | Q30: Qualified | R30: 569000 | S30: 0.35 | T30: =R30*S30 -> 199150 | U30: 11-03-2025
A31: LD2030 | B31: Zenith Retail | C31: Logistics | D31: Mid-Market (51-500) | E31: Vivaan | F31: IT Manager | G31: vivaan@zenith.com | H31: Inbound - Website | I31: 24-08-2025 | J31: Rohit Malhotra | K31: 2 | L31: 1 | M31: 2 | N31: 2 | O31: =SUM(K31:N31) -> 7 | P31: =IF(O31>=15,"Yes","No") -> No | Q31: Contacted | R31: 678000 | S31: 0.15 | T31: =R31*S31 -> 101700 | U31: 05-11-2025
A32: LD2031 | B32: Anchor Retail | C32: Education | D32: Small (1-50) | E32: Yash | F32: Founder/CEO | G32: yash@anchor.com | H32: Inbound - Website | I32: 18-03-2026 | J32: Divya Nair | K32: 3 | L32: 1 | M32: 3 | N32: 4 | O32: =SUM(K32:N32) -> 11 | P32: =IF(O32>=15,"Yes","No") -> No | Q32: Contacted | R32: 211000 | S32: 0.15 | T32: =R32*S32 -> 31650 | U32: 21-05-2026
A33: LD2032 | B33: Crestline Group | C33: E-commerce | D33: Small (1-50) | E33: Ishita | F33: IT Manager | G33: ishita@crestline.com | H33: Inbound - Website | I33: 11-06-2025 | J33: Sneha Iyer | K33: 5 | L33: 4 | M33: 3 | N33: 4 | O33: =SUM(K33:N33) -> 16 | P33: =IF(O33>=15,"Yes","No") -> Yes | Q33: New Lead | R33: 169000 | S33: 0.05 | T33: =R33*S33 -> 8450 | U33: 05-08-2025
A34: LD2033 | B34: Anchor Solutions | C34: E-commerce | D34: Small (1-50) | E34: Tanya | F34: Head of Operations | G34: tanya@anchor.com | H34: Inbound - Website | I34: 12-08-2025 | J34: Karan Bhatia | K34: 4 | L34: 4 | M34: 2 | N34: 3 | O34: =SUM(K34:N34) -> 13 | P34: =IF(O34>=15,"Yes","No") -> No | Q34: Closed Lost | R34: 249000 | S34: 0 | T34: =R34*S34 -> 0 | U34: 02-09-2025 | V34: 21-09-2025 | W34: 40 | X34: Budget too high
A35: LD2034 | B35: Quartz Industries | C35: Healthcare | D35: Mid-Market (51-500) | E35: Sana | F35: Founder/CEO | G35: sana@quartz.com | H35: LinkedIn Outreach | I35: 08-06-2025 | J35: Karan Bhatia | K35: 2 | L35: 3 | M35: 2 | N35: 2 | O35: =SUM(K35:N35) -> 9 | P35: =IF(O35>=15,"Yes","No") -> No | Q35: New Lead | R35: 905000 | S35: 0.05 | T35: =R35*S35 -> 45250 | U35: 13-08-2025
A36: LD2035 | B36: Redshift Industries | C36: FMCG | D36: Mid-Market (51-500) | E36: Aarav | F36: Marketing Director | G36: aarav@redshift.com | H36: Trade Show/Event | I36: 14-02-2025 | J36: Karan Bhatia | K36: 3 | L36: 4 | M36: 2 | N36: 3 | O36: =SUM(K36:N36) -> 12 | P36: =IF(O36>=15,"Yes","No") -> No | Q36: New Lead | R36: 617000 | S36: 0.05 | T36: =R36*S36 -> 30850 | U36: 26-04-2025
A37: LD2036 | B37: Foxglove Ventures | C37: E-commerce | D37: Small (1-50) | E37: Vivaan | F37: Head of Operations | G37: vivaan@foxglove.com | H37: Referral | I37: 29-03-2025 | J37: Ananya Kapoor | K37: 5 | L37: 2 | M37: 1 | N37: 2 | O37: =SUM(K37:N37) -> 10 | P37: =IF(O37>=15,"Yes","No") -> No | Q37: Closed Lost | R37: 147000 | S37: 0 | T37: =R37*S37 -> 0 | U37: 22-04-2025 | V37: 25-04-2025 | W37: 27 | X37: Chose competitor
A38: LD2037 | B38: Ridge Traders | C38: E-commerce | D38: Small (1-50) | E38: Aditya | F38: COO | G38: aditya@ridge.com | H38: Inbound - Website | I38: 01-05-2026 | J38: Rohit Malhotra | K38: 4 | L38: 4 | M38: 2 | N38: 4 | O38: =SUM(K38:N38) -> 14 | P38: =IF(O38>=15,"Yes","No") -> No | Q38: Proposal Sent | R38: 227000 | S38: 0.55 | T38: =R38*S38 -> 124850 | U38: 01-07-2026
A39: LD2038 | B39: Orbit Group | C39: Manufacturing | D39: Mid-Market (51-500) | E39: Pooja | F39: IT Manager | G39: pooja@orbit.com | H39: LinkedIn Outreach | I39: 18-09-2025 | J39: Rohit Malhotra | K39: 2 | L39: 2 | M39: 1 | N39: 3 | O39: =SUM(K39:N39) -> 8 | P39: =IF(O39>=15,"Yes","No") -> No | Q39: Contacted | R39: 704000 | S39: 0.15 | T39: =R39*S39 -> 105600 | U39: 20-11-2025
A40: LD2039 | B40: Anchor Mart | C40: Retail | D40: Mid-Market (51-500) | E40: Vivaan | F40: Procurement Manager | G40: vivaan@anchor.com | H40: Cold Outbound | I40: 20-10-2025 | J40: Divya Nair | K40: 1 | L40: 2 | M40: 1 | N40: 3 | O40: =SUM(K40:N40) -> 7 | P40: =IF(O40>=15,"Yes","No") -> No | Q40: Contacted | R40: 865000 | S40: 0.15 | T40: =R40*S40 -> 129750 | U40: 10-11-2025
...

Sheet Funnel Summary
B2: B2B Sales Pipeline — Funnel Summary
B4: Stage | C4: Leads | D4: Stage Value (INR) | E4: Weighted Value (INR) | F4: % of Total Leads | G4: Conversion from Prev Stage %
B5: New Lead | C5: =COUNTIFS(Pipeline!$Q$2:$Q$601,B5) -> 160 | D5: =SUMIFS(Pipeline!$R$2:$R$601,Pipeline!$Q$2:$Q$601,B5) -> 127861000 | E5: =SUMIFS(Pipeline!$T$2:$T$601,Pipeline!$Q$2:$Q$601,B5) -> 6393050 | F5: =C5/COUNTA(Pipeline!$A$2:$A$601) -> 0.26666667 | G5: —
B6: Contacted | C6: =COUNTIFS(Pipeline!$Q$2:$Q$601,B6) -> 203 | D6: =SUMIFS(Pipeline!$R$2:$R$601,Pipeline!$Q$2:$Q$601,B6) -> 140891000 | E6: =SUMIFS(Pipeline!$T$2:$T$601,Pipeline!$Q$2:$Q$601,B6) -> 21133650 | F6: =C6/COUNTA(Pipeline!$A$2:$A$601) -> 0.33833333 | G6: =IFERROR(C6/C5,"—") -> 1.26875
B7: Qualified | C7: =COUNTIFS(Pipeline!$Q$2:$Q$601,B7) -> 54 | D7: =SUMIFS(Pipeline!$R$2:$R$601,Pipeline!$Q$2:$Q$601,B7) -> 35682000 | E7: =SUMIFS(Pipeline!$T$2:$T$601,Pipeline!$Q$2:$Q$601,B7) -> 12488700 | F7: =C7/COUNTA(Pipeline!$A$2:$A$601) -> 0.09 | G7: =IFERROR(C7/C6,"—") -> 0.26600985
B8: Proposal Sent | C8: =COUNTIFS(Pipeline!$Q$2:$Q$601,B8) -> 29 | D8: =SUMIFS(Pipeline!$R$2:$R$601,Pipeline!$Q$2:$Q$601,B8) -> 26399000 | E8: =SUMIFS(Pipeline!$T$2:$T$601,Pipeline!$Q$2:$Q$601,B8) -> 14519450 | F8: =C8/COUNTA(Pipeline!$A$2:$A$601) -> 0.048333333 | G8: =IFERROR(C8/C7,"—") -> 0.53703704
B9: Negotiation | C9: =COUNTIFS(Pipeline!$Q$2:$Q$601,B9) -> 0 | D9: =SUMIFS(Pipeline!$R$2:$R$601,Pipeline!$Q$2:$Q$601,B9) -> 0 | E9: =SUMIFS(Pipeline!$T$2:$T$601,Pipeline!$Q$2:$Q$601,B9) -> 0 | F9: =C9/COUNTA(Pipeline!$A$2:$A$601) -> 0 | G9: =IFERROR(C9/C8,"—") -> 0
B10: Closed Won | C10: =COUNTIFS(Pipeline!$Q$2:$Q$601,B10) -> 40 | D10: =SUMIFS(Pipeline!$R$2:$R$601,Pipeline!$Q$2:$Q$601,B10) -> 27963000 | E10: =SUMIFS(Pipeline!$T$2:$T$601,Pipeline!$Q$2:$Q$601,B10) -> 27963000 | F10: =C10/COUNTA(Pipeline!$A$2:$A$601) -> 0.066666667 | G10: =IFERROR(C10/C9,"—") -> —
B11: Closed Lost | C11: =COUNTIFS(Pipeline!$Q$2:$Q$601,B11) -> 114 | D11: =SUMIFS(Pipeline!$R$2:$R$601,Pipeline!$Q$2:$Q$601,B11) -> 82753000 | E11: =SUMIFS(Pipeline!$T$2:$T$601,Pipeline!$Q$2:$Q$601,B11) -> 0 | F11: =C11/COUNTA(Pipeline!$A$2:$A$601) -> 0.19 | G11: =IFERROR(C11/C10,"—") -> 2.85
B14: Overall Win Rate (Closed Won / Closed Won+Lost) | D14: =COUNTIFS(Pipeline!$Q$2:$Q$601,"Closed Won")/(COUNTIFS(Pipeline!$Q$2:$Q$601,"Closed Won")+COUNTIFS(Pipeline!$Q$2:$Q$601,"Closed Lost")) -> 0.25974026
B15: Total Open Pipeline Value (INR) | D15: =SUMIFS(Pipeline!$R$2:$R$601,Pipeline!$Q$2:$Q$601,"<>Closed Won",Pipeline!$Q$2:$Q$601,"<>Closed Lost") -> 330833000
B16: Weighted Open Pipeline Value (INR) | D16: =SUMIFS(Pipeline!$T$2:$T$601,Pipeline!$Q$2:$Q$601,"<>Closed Won",Pipeline!$Q$2:$Q$601,"<>Closed Lost") -> 54534850
B17: Closed Won Revenue (INR) | D17: =SUMIFS(Pipeline!$R$2:$R$601,Pipeline!$Q$2:$Q$601,"Closed Won") -> 27963000
B18: Average Deal Size — Closed Won (INR) | D18: =AVERAGEIFS(Pipeline!$R$2:$R$601,Pipeline!$Q$2:$Q$601,"Closed Won") -> 699075

Sheet Lead Source Analysis
A1: Lead Source | B1: Total Leads | C1: Deals Won | D1: Win Rate % | E1: Revenue Won (INR)
A2: Cold Outbound | B2: =COUNTIFS(Pipeline!$H$2:$H$601,A2) -> 173 | C2: =COUNTIFS(Pipeline!$H$2:$H$601,A2,Pipeline!$Q$2:$Q$601,"Closed Won") -> 4 | D2: =IFERROR(C2/B2,0) -> 0.023121387 | E2: =SUMIFS(Pipeline!$R$2:$R$601,Pipeline!$H$2:$H$601,A2,Pipeline!$Q$2:$Q$601,"Closed Won") -> 2538000
A3: Inbound - Website | B3: =COUNTIFS(Pipeline!$H$2:$H$601,A3) -> 132 | C3: =COUNTIFS(Pipeline!$H$2:$H$601,A3,Pipeline!$Q$2:$Q$601,"Closed Won") -> 13 | D3: =IFERROR(C3/B3,0) -> 0.098484848 | E3: =SUMIFS(Pipeline!$R$2:$R$601,Pipeline!$H$2:$H$601,A3,Pipeline!$Q$2:$Q$601,"Closed Won") -> 5936000
A4: LinkedIn Outreach | B4: =COUNTIFS(Pipeline!$H$2:$H$601,A4) -> 103 | C4: =COUNTIFS(Pipeline!$H$2:$H$601,A4,Pipeline!$Q$2:$Q$601,"Closed Won") -> 2 | D4: =IFERROR(C4/B4,0) -> 0.019417476 | E4: =SUMIFS(Pipeline!$R$2:$R$601,Pipeline!$H$2:$H$601,A4,Pipeline!$Q$2:$Q$601,"Closed Won") -> 1000000
A5: Partner Channel | B5: =COUNTIFS(Pipeline!$H$2:$H$601,A5) -> 54 | C5: =COUNTIFS(Pipeline!$H$2:$H$601,A5,Pipeline!$Q$2:$Q$601,"Closed Won") -> 5 | D5: =IFERROR(C5/B5,0) -> 0.092592593 | E5: =SUMIFS(Pipeline!$R$2:$R$601,Pipeline!$H$2:$H$601,A5,Pipeline!$Q$2:$Q$601,"Closed Won") -> 2165000
A6: Referral | B6: =COUNTIFS(Pipeline!$H$2:$H$601,A6) -> 84 | C6: =COUNTIFS(Pipeline!$H$2:$H$601,A6,Pipeline!$Q$2:$Q$601,"Closed Won") -> 12 | D6: =IFERROR(C6/B6,0) -> 0.14285714 | E6: =SUMIFS(Pipeline!$R$2:$R$601,Pipeline!$H$2:$H$601,A6,Pipeline!$Q$2:$Q$601,"Closed Won") -> 9646000
A7: Trade Show/Event | B7: =COUNTIFS(Pipeline!$H$2:$H$601,A7) -> 54 | C7: =COUNTIFS(Pipeline!$H$2:$H$601,A7,Pipeline!$Q$2:$Q$601,"Closed Won") -> 4 | D7: =IFERROR(C7/B7,0) -> 0.074074074 | E7: =SUMIFS(Pipeline!$R$2:$R$601,Pipeline!$H$2:$H$601,A7,Pipeline!$Q$2:$Q$601,"Closed Won") -> 6678000

Sheet Sales Rep Leaderboard
A1: Sales Rep | B1: Leads Owned | C1: Deals Won | D1: Win Rate % | E1: Revenue Closed (INR)
A2: Ananya Kapoor | B2: =COUNTIFS(Pipeline!$J$2:$J$601,A2) -> 114 | C2: =COUNTIFS(Pipeline!$J$2:$J$601,A2,Pipeline!$Q$2:$Q$601,"Closed Won") -> 13 | D2: =IFERROR(C2/B2,0) -> 0.11403509 | E2: =SUMIFS(Pipeline!$R$2:$R$601,Pipeline!$J$2:$J$601,A2,Pipeline!$Q$2:$Q$601,"Closed Won") -> 9182000
A3: Divya Nair | B3: =COUNTIFS(Pipeline!$J$2:$J$601,A3) -> 120 | C3: =COUNTIFS(Pipeline!$J$2:$J$601,A3,Pipeline!$Q$2:$Q$601,"Closed Won") -> 7 | D3: =IFERROR(C3/B3,0) -> 0.058333333 | E3: =SUMIFS(Pipeline!$R$2:$R$601,Pipeline!$J$2:$J$601,A3,Pipeline!$Q$2:$Q$601,"Closed Won") -> 5963000
A4: Karan Bhatia | B4: =COUNTIFS(Pipeline!$J$2:$J$601,A4) -> 117 | C4: =COUNTIFS(Pipeline!$J$2:$J$601,A4,Pipeline!$Q$2:$Q$601,"Closed Won") -> 2 | D4: =IFERROR(C4/B4,0) -> 0.017094017 | E4: =SUMIFS(Pipeline!$R$2:$R$601,Pipeline!$J$2:$J$601,A4,Pipeline!$Q$2:$Q$601,"Closed Won") -> 2947000
A5: Rohit Malhotra | B5: =COUNTIFS(Pipeline!$J$2:$J$601,A5) -> 125 | C5: =COUNTIFS(Pipeline!$J$2:$J$601,A5,Pipeline!$Q$2:$Q$601,"Closed Won") -> 3 | D5: =IFERROR(C5/B5,0) -> 0.024 | E5: =SUMIFS(Pipeline!$R$2:$R$601,Pipeline!$J$2:$J$601,A5,Pipeline!$Q$2:$Q$601,"Closed Won") -> 2559000
A6: Sneha Iyer | B6: =COUNTIFS(Pipeline!$J$2:$J$601,A6) -> 124 | C6: =COUNTIFS(Pipeline!$J$2:$J$601,A6,Pipeline!$Q$2:$Q$601,"Closed Won") -> 15 | D6: =IFERROR(C6/B6,0) -> 0.12096774 | E6: =SUMIFS(Pipeline!$R$2:$R$601,Pipeline!$J$2:$J$601,A6,Pipeline!$Q$2:$Q$601,"Closed Won") -> 7312000

Sheet BANT Matrix
B2: BANT Qualification Scoring Rubric
B4: Score | C4: Budget | D4: Authority | E4: Need | F4: Timeline
B5: 1 | C5: No budget allocated | D5: Individual contributor | E5: Vague interest | F5: No timeline
B6: 3 | C6: Budget exists, needs approval | D6: Influences decision | E6: Acknowledged problem | F6: Buying in 2 quarters
B7: 5 | C7: Budget confirmed & approved | D7: Final decision-maker | E7: Clear quantified pain point | F7: Buying in 30-60 days
B10: Win Rate by BANT Score Band (live from Pipeline data)
B11: BANT Band | C11: Leads | D11: Deals Won | E11: Win Rate %
B12: 0-10 (Poor fit) | C12: =COUNTIFS(Pipeline!$O$2:$O$601,">="&0,Pipeline!$O$2:$O$601,"<="&10) -> 308 | D12: =COUNTIFS(Pipeline!$O$2:$O$601,">="&0,Pipeline!$O$2:$O$601,"<="&10,Pipeline!$Q$2:$Q$601,"Closed Won") -> 8 | E12: =IFERROR(D12/C12,0) -> 0.025974026
B13: 11-14 (Weak fit) | C13: =COUNTIFS(Pipeline!$O$2:$O$601,">="&11,Pipeline!$O$2:$O$601,"<="&14) -> 204 | D13: =COUNTIFS(Pipeline!$O$2:$O$601,">="&11,Pipeline!$O$2:$O$601,"<="&14,Pipeline!$Q$2:$Q$601,"Closed Won") -> 17 | E13: =IFERROR(D13/C13,0) -> 0.083333333
B14: 15-17 (Good fit) | C14: =COUNTIFS(Pipeline!$O$2:$O$601,">="&15,Pipeline!$O$2:$O$601,"<="&17) -> 68 | D14: =COUNTIFS(Pipeline!$O$2:$O$601,">="&15,Pipeline!$O$2:$O$601,"<="&17,Pipeline!$Q$2:$Q$601,"Closed Won") -> 9 | E14: =IFERROR(D14/C14,0) -> 0.13235294
B15: 18-20 (Strong fit) | C15: =COUNTIFS(Pipeline!$O$2:$O$601,">="&18,Pipeline!$O$2:$O$601,"<="&20) -> 20 | D15: =COUNTIFS(Pipeline!$O$2:$O$601,">="&18,Pipeline!$O$2:$O$601,"<="&20,Pipeline!$Q$2:$Q$601,"Closed Won") -> 6 | E15: =IFERROR(D15/C15,0) -> 0.3

Sheet Lost Reason Analysis
A1: Lost Reason | B1: Deals Lost | C1: Revenue Lost (INR)
A2: Bad timing | B2: =COUNTIFS(Pipeline!$X$2:$X$601,A2) -> 10 | C2: =SUMIFS(Pipeline!$R$2:$R$601,Pipeline!$X$2:$X$601,A2) -> 7536000
A3: Budget too high | B3: =COUNTIFS(Pipeline!$X$2:$X$601,A3) -> 23 | C3: =SUMIFS(Pipeline!$R$2:$R$601,Pipeline!$X$2:$X$601,A3) -> 16668000
A4: Chose competitor | B4: =COUNTIFS(Pipeline!$X$2:$X$601,A4) -> 32 | C4: =SUMIFS(Pipeline!$R$2:$R$601,Pipeline!$X$2:$X$601,A4) -> 26354000
A5: Feature gap | B5: =COUNTIFS(Pipeline!$X$2:$X$601,A5) -> 12 | C5: =SUMIFS(Pipeline!$R$2:$R$601,Pipeline!$X$2:$X$601,A5) -> 9764000
A6: No decision / went dark | B6: =COUNTIFS(Pipeline!$X$2:$X$601,A6) -> 28 | C6: =SUMIFS(Pipeline!$R$2:$R$601,Pipeline!$X$2:$X$601,A6) -> 17314000
A7: Not enough authority to buy | B7: =COUNTIFS(Pipeline!$X$2:$X$601,A7) -> 9 | C7: =SUMIFS(Pipeline!$R$2:$R$601,Pipeline!$X$2:$X$601,A7) -> 5117000
